<?xml version="1.0" encoding="utf-8"?>
<!-- This URDF was automatically created by SolidWorks to URDF Exporter! Originally created by Stephen Brawner (brawner@gmail.com) 
     Commit Version: 1.6.0-4-g7f85cfe  Build Version: 1.6.7995.38578
     For more information, please see http://wiki.ros.org/sw_urdf_exporter -->
<robot
  name="H780bv2.SLDASM">
  <link
    name="base_link">
    <inertial>
      <origin
        xyz="-2.6038E-08 -1.5225E-08 0.00010799"
        rpy="0 0 0" />
      <mass
        value="0.95598158" />
      <inertia
        ixx="0.00153865"
        ixy="-0.00000000"
        ixz="-0.00000000"
        iyy="0.00047315"
        iyz="-0.00000000"
        izz="0.00153145" />
    </inertial>
    <visual>
      <origin
        xyz="0 0 0"
        rpy="0 0 0" />
      <geometry>
        <mesh
          filename="meshes/base_link.STL" />
      </geometry>
      <material
        name="">
        <color
          rgba="0.75294 0.75294 0.75294 1" />
      </material>
    </visual>
    <collision>
      <origin
        xyz="0 0 0"
        rpy="0 0 0" />
      <geometry>
        <mesh
          filename="meshes/base_link.STL" />
      </geometry>
    </collision>
  </link>
  <link
    name="left_hip_pitch_link">
    <inertial>
      <origin
        xyz="-0.01046 0.034126 -0.01669"
        rpy="0 0 0" />
      <mass
        value="0.35474682" />
      <inertia
        ixx=" 0.00018206"
        ixy="0.00000364"
        ixz="-0.00000336"
        iyy="0.00017411"
        iyz="0.00000675"
        izz="0.00017567" />
    </inertial>
    <visual>
      <origin
        xyz="0 0 0"
        rpy="0 0 0" />
      <geometry>
        <mesh
          filename="meshes/left_hip_pitch_link.STL" />
      </geometry>
      <material
        name="">
        <color
          rgba="0.75294 0.75294 0.75294 1" />
      </material>
    </visual>
    <collision>
      <origin
        xyz="0 0 0"
        rpy="0 0 0" />
      <geometry>
        <mesh
          filename="meshes/left_hip_pitch_link.STL" />
      </geometry>
    </collision>
  </link>
  <joint
    name="left_hip_pitch_joint"
    type="revolute">
    <origin
      xyz="0 0.0615 0"
      rpy="0 0 0" />
    <parent
      link="base_link" />
    <child
      link="left_hip_pitch_link" />
    <axis
      xyz="0 1 0" />
    <limit
      lower="-2.5307"
      upper="2.8798"
      effort="48"
      velocity="12.566" />
  </joint>
  <link
    name="left_hip_roll_link">
    <inertial>
      <origin
        xyz="0.000563729674484424 0.00024023402195833 -0.0575005489611565"
        rpy="0 0 0" />
      <mass
        value="0.39903545" />
      <inertia
        ixx="0.00032320"
        ixy="-0.00000013"
        ixz="-0.00001876"
        iyy=" 0.00031641"
        iyz="-0.00000314"
        izz="0.00019315" />
    </inertial>
    <visual>
      <origin
        xyz="0 0 0"
        rpy="0 0 0" />
      <geometry>
        <mesh
          filename="meshes/left_hip_roll_link.STL" />
      </geometry>
      <material
        name="">
        <color
          rgba="0.752941176470588 0.752941176470588 0.752941176470588 1" />
      </material>
    </visual>
    <collision>
      <origin
        xyz="0 0 0"
        rpy="0 0 0" />
      <geometry>
        <mesh
          filename="meshes/left_hip_roll_link.STL" />
      </geometry>
    </collision>
  </link>
  <joint
    name="left_hip_roll_joint"
    type="revolute">
    <origin
      xyz="0.012045 0.035 -0.017465"
      rpy="0 0 0" />
    <parent
      link="left_hip_pitch_link" />
    <child
      link="left_hip_roll_link" />
    <axis
      xyz="1 0 0" />
    <limit
      lower="-0.5236"
      upper="2.9671"
      effort="14"
      velocity="27.227" />
  </joint>
  <link
    name="left_hip_yaw_link">
    <inertial>
      <origin
        xyz="-0.00830577126112742 -0.00401954499943484 -0.054620366884708"
        rpy="0 0 0" />
      <mass
        value=" 0.10725703" />
      <inertia
        ixx="0.00014635"
        ixy="-0.00000901"
        ixz="-0.00002146"
        iyy="0.00012544"
        iyz="-0.00001437"
        izz="0.00009017" />
    </inertial>
    <visual>
      <origin
        xyz="0 0 0"
        rpy="0 0 0" />
      <geometry>
        <mesh
          filename="meshes/left_hip_yaw_link.STL" />
      </geometry>
      <material
        name="">
        <color
          rgba="0.752941176470588 0.752941176470588 0.752941176470588 1" />
      </material>
    </visual>
    <collision>
      <origin
        xyz="0 0 0"
        rpy="0 0 0" />
      <geometry>
        <mesh
          filename="meshes/left_hip_yaw_link.STL" />
      </geometry>
    </collision>
  </link>
  <joint
    name="left_hip_yaw_joint"
    type="revolute">
    <origin
      xyz="-0.0014 0 -0.089035"
      rpy="0 0 0" />
    <parent
      link="left_hip_roll_link" />
    <child
      link="left_hip_yaw_link" />
    <axis
      xyz="0 0 1" />
    <limit
      lower="-2.7576"
      upper="2.7576"
      effort="14"
      velocity="27.227" />
  </joint>
  <link
    name="left_knee_pitch_link">
    <inertial>
      <origin
        xyz="0.00287073056298838 -0.0305282117653435 -0.0589489776360531"
        rpy="0 0 0" />
      <mass
        value="1.28968322" />
      <inertia
        ixx="0.00399533"
        ixy="0.00000523"
        ixz="0.00016959"
        iyy="0.00395825"
        iyz="-0.00003804"
        izz="0.00073178" />
    </inertial>
    <visual>
      <origin
        xyz="0 0 0"
        rpy="0 0 0" />
      <geometry>
        <mesh
          filename="meshes/left_knee_pitch_link.STL" />
      </geometry>
      <material
        name="">
        <color
          rgba="0.752941176470588 0.752941176470588 0.752941176470588 1" />
      </material>
    </visual>
    <collision>
      <origin
        xyz="0 0 0"
        rpy="0 0 0" />
      <geometry>
        <mesh
          filename="meshes/left_knee_pitch_link.STL" />
      </geometry>
    </collision>
  </link>
  <joint
    name="left_knee_pitch_joint"
    type="revolute">
    <origin
      xyz="-0.031116 0.031 -0.086991"
      rpy="0 0 0" />
    <parent
      link="left_hip_yaw_link" />
    <child
      link="left_knee_pitch_link" />
    <axis
      xyz="0 1 0" />
    <limit
      lower="-0.0872"
      upper="2.5307"
      effort="48"
      velocity="12.566" />
  </joint>
  <link
    name="left_ankle_pitch_link">
    <inertial>
      <origin
        xyz="-0.00431251433379506 -8.29255983325616E-10 -0.00392559144958809"
        rpy="0 0 0" />
      <mass
        value="0.01456651" />
      <inertia
        ixx="0.00000051"
        ixy="-0.00000000"
        ixz="-0.00000029"
        iyy="0.00000101"
        iyz="-0.00000000"
        izz="0.00000101" />
    </inertial>
    <visual>
      <origin
        xyz="0 0 0"
        rpy="0 0 0" />
      <geometry>
        <mesh
          filename="meshes/left_ankle_pitch_link.STL" />
      </geometry>
      <material
        name="">
        <color
          rgba="0.752941176470588 0.752941176470588 0.752941176470588 1" />
      </material>
    </visual>
    <collision>
      <origin
        xyz="0 0 0"
        rpy="0 0 0" />
      <geometry>
        <mesh
          filename="meshes/left_ankle_pitch_link.STL" />
      </geometry>
    </collision>
  </link>
  <joint
    name="left_ankle_pitch_jiont"
    type="revolute">
    <origin
      xyz="0.022233 -0.031 -0.19335"
      rpy="0 0 0" />
    <parent
      link="left_knee_pitch_link" />
    <child
      link="left_ankle_pitch_link" />
    <axis
      xyz="0 1 0" />
    <limit
      lower="-0.87267"
      upper="0.5236"
      effort="14"
      velocity="27.227" />
  </joint>
  <link
    name="left_ankle_roll_link">
    <inertial>
      <origin
        xyz="0.0386677603328724 -4.24243973284888E-14 -0.00796762666349413"
        rpy="0 0 0" />
      <mass
        value="0.06856823" />
      <inertia
        ixx="0.00001260"
        ixy="-0.00000000"
        ixz="0.00000235"
        iyy="0.00008138"
        iyz="-0.00000000"
        izz="0.00008990" />
    </inertial>
    <visual>
      <origin
        xyz="0 0 0"
        rpy="0 0 0" />
      <geometry>
        <mesh
          filename="meshes/left_ankle_roll_link.STL" />
      </geometry>
      <material
        name="">
        <color
          rgba="0.752941176470588 0.752941176470588 0.752941176470588 1" />
      </material>
    </visual>
    <collision>
      <origin
        xyz="0 0 0"
        rpy="0 0 0" />
      <geometry>
        <mesh
          filename="meshes/left_ankle_roll_link.STL" />
      </geometry>
    </collision>
  </link>
  <joint
    name="left_ankle_roll_joint"
    type="revolute">
    <origin
      xyz="-0.0255 0 -0.009"
      rpy="0 0 0" />
    <parent
      link="left_ankle_pitch_link" />
    <child
      link="left_ankle_roll_link" />
    <axis
      xyz="1 0 0" />
    <limit
      lower="-0.2618"
      upper="0.2618"
      effort="14"
      velocity="27.227" />
  </joint>
  <link
    name="right_hip_pitch_link">
    <inertial>
      <origin
        xyz="-0.0104598069751148 -0.0341257425653734 -0.0166901486909431"
        rpy="0 0 0" />
      <mass
        value="0.35474682" />
      <inertia
        ixx="0.00018206"
        ixy="-0.00000364"
        ixz="-0.00000336"
        iyy="0.00017411"
        iyz="-0.00000676"
        izz="0.00017567" />
    </inertial>
    <visual>
      <origin
        xyz="0 0 0"
        rpy="0 0 0" />
      <geometry>
        <mesh
          filename="meshes/right_hip_pitch_link.STL" />
      </geometry>
      <material
        name="">
        <color
          rgba="0.752941176470588 0.752941176470588 0.752941176470588 1" />
      </material>
    </visual>
    <collision>
      <origin
        xyz="0 0 0"
        rpy="0 0 0" />
      <geometry>
        <mesh
          filename="meshes/right_hip_pitch_link.STL" />
      </geometry>
    </collision>
  </link>
  <joint
    name="right_hip_pitch_joint"
    type="revolute">
    <origin
      xyz="0 -0.0615 0"
      rpy="0 0 0" />
    <parent
      link="base_link" />
    <child
      link="right_hip_pitch_link" />
    <axis
      xyz="0 1 0" />
    <limit
      lower="-2.5307"
      upper="2.8798"
      effort="48"
      velocity="12.566" />
  </joint>
  <link
    name="right_hip_roll_link">
    <inertial>
      <origin
        xyz="0.00056346775242555 -0.000240722361758011 -0.0575015521594692"
        rpy="0 0 0" />
      <mass
        value="0.39902529" />
      <inertia
        ixx="0.00032316"
        ixy="0.00000013"
        ixz="-0.00001875"
        iyy="0.00031642"
        iyz="0.00000314"
        izz="0.00019314" />
    </inertial>
    <visual>
      <origin
        xyz="0 0 0"
        rpy="0 0 0" />
      <geometry>
        <mesh
          filename="meshes/right_hip_roll_link.STL" />
      </geometry>
      <material
        name="">
        <color
          rgba="0.752941176470588 0.752941176470588 0.752941176470588 1" />
      </material>
    </visual>
    <collision>
      <origin
        xyz="0 0 0"
        rpy="0 0 0" />
      <geometry>
        <mesh
          filename="meshes/right_hip_roll_link.STL" />
      </geometry>
    </collision>
  </link>
  <joint
    name="right_hip_roll_joint"
    type="revolute">
    <origin
      xyz="0.012045 -0.035 -0.017465"
      rpy="0 0 0" />
    <parent
      link="right_hip_pitch_link" />
    <child
      link="right_hip_roll_link" />
    <axis
      xyz="1 0 0" />
    <limit
      lower="-0.5236"
      upper="2.9671"
      effort="14"
      velocity="27.227" />
  </joint>
  <link
    name="right_hip_yaw_link">
    <inertial>
      <origin
        xyz="-0.00830598192395614 0.00401981366216746 -0.054620871926642"
        rpy="0 0 0" />
      <mass
        value="0.10725593" />
      <inertia
        ixx="0.00014635"
        ixy="0.00000901"
        ixz="-0.00002146"
        iyy="0.00012544"
        iyz="0.00001437"
        izz="0.00009017" />
    </inertial>
    <visual>
      <origin
        xyz="0 0 0"
        rpy="0 0 0" />
      <geometry>
        <mesh
          filename="meshes/right_hip_yaw_link.STL" />
      </geometry>
      <material
        name="">
        <color
          rgba="0.752941176470588 0.752941176470588 0.752941176470588 1" />
      </material>
    </visual>
    <collision>
      <origin
        xyz="0 0 0"
        rpy="0 0 0" />
      <geometry>
        <mesh
          filename="meshes/right_hip_yaw_link.STL" />
      </geometry>
    </collision>
  </link>
  <joint
    name="right_hip_yaw_joint"
    type="revolute">
    <origin
      xyz="-0.0014 0 -0.089035"
      rpy="0 0 0" />
    <parent
      link="right_hip_roll_link" />
    <child
      link="right_hip_yaw_link" />
    <axis
      xyz="0 0 1" />
    <limit
      lower="-2.7576"
      upper="2.7576"
      effort="14"
      velocity="27.227" />
  </joint>
  <link
    name="right_knee_pitch_link">
    <inertial>
      <origin
        xyz="0.00313962927887962 0.03043348410326 -0.0596560390278527"
        rpy="0 0 0" />
      <mass
        value="1.29925656" />
      <inertia
        ixx="0.00409085"
        ixy="-0.00000073"
        ixz="0.00020256"
        iyy="0.00406476"
        iyz="0.00002715"
        izz="0.00074624" />
    </inertial>
    <visual>
      <origin
        xyz="0 0 0"
        rpy="0 0 0" />
      <geometry>
        <mesh
          filename="meshes/right_knee_pitch_link.STL" />
      </geometry>
      <material
        name="">
        <color
          rgba="0.752941176470588 0.752941176470588 0.752941176470588 1" />
      </material>
    </visual>
    <collision>
      <origin
        xyz="0 0 0"
        rpy="0 0 0" />
      <geometry>
        <mesh
          filename="meshes/right_knee_pitch_link.STL" />
      </geometry>
    </collision>
  </link>
  <joint
    name="right_knee_pitch_jpint"
    type="revolute">
    <origin
      xyz="-0.031116 -0.031 -0.086991"
      rpy="0 0 0" />
    <parent
      link="right_hip_yaw_link" />
    <child
      link="right_knee_pitch_link" />
    <axis
      xyz="0 1 0" />
    <limit
      lower="-0.0872"
      upper="2.5307"
      effort="48"
      velocity="12.566" />
  </joint>
  <link
    name="right_ankle_pitch_link">
    <inertial>
      <origin
        xyz="-0.00431251615337302 5.17639613117904E-09 -0.00392561148944627"
        rpy="0 0 0" />
      <mass
        value="0.01456653" />
      <inertia
        ixx=" 0.00000051"
        ixy="-0.00000000"
        ixz="-0.00000029"
        iyy="0.00000101"
        iyz="-0.00000000"
        izz="0.00000091" />
    </inertial>
    <visual>
      <origin
        xyz="0 0 0"
        rpy="0 0 0" />
      <geometry>
        <mesh
          filename="meshes/right_ankle_pitch_link.STL" />
      </geometry>
      <material
        name="">
        <color
          rgba="0.752941176470588 0.752941176470588 0.752941176470588 1" />
      </material>
    </visual>
    <collision>
      <origin
        xyz="0 0 0"
        rpy="0 0 0" />
      <geometry>
        <mesh
          filename="meshes/right_ankle_pitch_link.STL" />
      </geometry>
    </collision>
  </link>
  <joint
    name="right_ankle_pitch_joint"
    type="revolute">
    <origin
      xyz="0.022233 0.031 -0.19335"
      rpy="0 0 0" />
    <parent
      link="right_knee_pitch_link" />
    <child
      link="right_ankle_pitch_link" />
    <axis
      xyz="0 1 0" />
    <limit
      lower="-0.87267"
      upper="0.5236"
      effort="14"
      velocity="27.227" />
  </joint>
  <link
    name="right_ankle_roll_link">
    <inertial>
      <origin
        xyz="0.0386754555348046 -4.92522689299335E-14 -0.00796965904822458"
        rpy="0 0 0" />
      <mass
        value="0.06855075" />
      <inertia
        ixx="0.00001260"
        ixy="-0.00000000"
        ixz="0.00000234"
        iyy="0.00008137"
        iyz="-0.00000000"
        izz="0.00008988" />
    </inertial>
    <visual>
      <origin
        xyz="0 0 0"
        rpy="0 0 0" />
      <geometry>
        <mesh
          filename="meshes/right_ankle_roll_link.STL" />
      </geometry>
      <material
        name="">
        <color
          rgba="0.752941176470588 0.752941176470588 0.752941176470588 1" />
      </material>
    </visual>
    <collision>
      <origin
        xyz="0 0 0"
        rpy="0 0 0" />
      <geometry>
        <mesh
          filename="meshes/right_ankle_roll_link.STL" />
      </geometry>
    </collision>
  </link>
  <joint
    name="right_ankle_roll_joint"
    type="revolute">
    <origin
      xyz="-0.0255 0 -0.009"
      rpy="0 0 0" />
    <parent
      link="right_ankle_pitch_link" />
    <child
      link="right_ankle_roll_link" />
    <axis
      xyz="1 0 0" />
    <limit
      lower="-0.2618"
      upper="0.2618"
      effort="14"
      velocity="27.227" />
  </joint>
  <link
    name="waist_yaw_link">
    <inertial>
      <origin
        xyz="0.000220259410381247 -1.63108214940095E-10 0.0222310194297843"
        rpy="0 0 0" />
      <mass
        value="0.46789364" />
      <inertia
        ixx="0.00028104"
        ixy="-0.00000000"
        ixz="-0.00000345"
        iyy="0.00026173"
        iyz="-0.00000000"
        izz="0.00038609" />
    </inertial>
    <visual>
      <origin
        xyz="0 0 0"
        rpy="0 0 0" />
      <geometry>
        <mesh
          filename="meshes/waist_yaw_link.STL" />
      </geometry>
      <material
        name="">
        <color
          rgba="0.752941176470588 0.752941176470588 0.752941176470588 1" />
      </material>
    </visual>
    <collision>
      <origin
        xyz="0 0 0"
        rpy="0 0 0" />
      <geometry>
        <mesh
          filename="meshes/waist_yaw_link.STL" />
      </geometry>
    </collision>
  </link>
  <joint
    name="waist_yaw_joint"
    type="revolute">
    <origin
      xyz="0 0 0.034"
      rpy="0 0 0" />
    <parent
      link="base_link" />
    <child
      link="waist_yaw_link" />
    <axis
      xyz="0 0 1" />
    <limit
      lower="-1.9722"
      upper="1.9722"
      effort="17"
      velocity="28.798" />
  </joint>
  <link
    name="waist_roll_link">
    <inertial>
      <origin
        xyz="0 1.45188006205474E-18 -3.33066907387547E-16"
        rpy="0 0 0" />
      <mass
        value="0.01851625" />
      <inertia
        ixx="0.00000131"
        ixy="-0.00000000"
        ixz="-0.00000000"
        iyy="0.00000063"
        iyz="-0.00000000"
        izz="0.00000174" />
    </inertial>
    <visual>
      <origin
        xyz="0 0 0"
        rpy="0 0 0" />
      <geometry>
        <mesh
          filename="meshes/waist_roll_link.STL" />
      </geometry>
      <material
        name="">
        <color
          rgba="0.752941176470588 0.752941176470588 0.752941176470588 1" />
      </material>
    </visual>
    <collision>
      <origin
        xyz="0 0 0"
        rpy="0 0 0" />
      <geometry>
        <mesh
          filename="meshes/waist_roll_link.STL" />
      </geometry>
    </collision>
  </link>
  <joint
    name="waist_roll_joint"
    type="revolute">
    <origin
      xyz="0 0 0.0602"
      rpy="0 0 0" />
    <parent
      link="waist_yaw_link" />
    <child
      link="waist_roll_link" />
    <axis
      xyz="1 0 0" />
    <limit
      lower="-0.7853"
      upper="0.7853"
      effort="14"
      velocity="27.227" />
  </joint>
  <link
    name="waist_pitch_link">
    <inertial>
      <origin
        xyz="-0.00563569340688714 5.32490978293959E-05 0.0994650407291855"
        rpy="0 0 0" />
      <mass
        value="1.86684803" />
      <inertia
        ixx="0.00817573"
        ixy="0.00000021"
        ixz="-0.00049361"
        iyy="0.00422033"
        iyz="-0.00000002"
        izz="0.00526790" />
    </inertial>
    <visual>
      <origin
        xyz="0 0 0"
        rpy="0 0 0" />
      <geometry>
        <mesh
          filename="meshes/waist_pitch_link.STL" />
      </geometry>
      <material
        name="">
        <color
          rgba="0.752941176470588 0.752941176470588 0.752941176470588 1" />
      </material>
    </visual>
    <collision>
      <origin
        xyz="0 0 0"
        rpy="0 0 0" />
      <geometry>
        <mesh
          filename="meshes/waist_pitch_link.STL" />
      </geometry>
    </collision>
  </link>
  <joint
    name="waist_pitch_joint"
    type="revolute">
    <origin
      xyz="0 0 0"
      rpy="0 0 0" />
    <parent
      link="waist_roll_link" />
    <child
      link="waist_pitch_link" />
    <axis
      xyz="0 1 0" />
    <limit
      lower="-0.5235"
      upper="0.5235"
      effort="14"
      velocity="27.227" />
  </joint>
  <link
    name="imu_link">
    <inertial>
      <origin
        xyz="-4.33680868994202E-19 0 -0.00250000000000006"
        rpy="0 0 0" />
      <mass
        value="0.00050000" />
      <inertia
        ixx="0.00000000"
        ixy="-0.00000000"
        ixz="-0.00000000"
        iyy="0.00000000"
        iyz="-0.00000000"
        izz="0.00000000" />
    </inertial>
    <visual>
      <origin
        xyz="0 0 0"
        rpy="0 0 0" />
      <geometry>
        <mesh
          filename="meshes/imu_link.STL" />
      </geometry>
      <material
        name="">
        <color
          rgba="0.792156862745098 0.819607843137255 0.933333333333333 1" />
      </material>
    </visual>
    <collision>
      <origin
        xyz="0 0 0"
        rpy="0 0 0" />
      <geometry>
        <mesh
          filename="meshes/imu_link.STL" />
      </geometry>
    </collision>
  </link>
  <joint
    name="imu_joinit"
    type="fixed">
    <origin
      xyz="-0.00205 0.00415 0.1097"
      rpy="0 0 0" />
    <parent
      link="waist_pitch_link" />
    <child
      link="imu_link" />
    <axis
      xyz="0 0 0" />
  </joint>
  <link
    name="left_shoulder_pitch_link">
    <inertial>
      <origin
        xyz="-0.0007726804859487 0.0281035423352152 1.11022302462516E-16"
        rpy="0 0 0" />
      <mass
        value="0.22917007" />
      <inertia
        ixx="0.00007116"
        ixy="0.00000034"
        ixz="-0.00000000"
        iyy="0.00007802"
        iyz="-0.00000000"
        izz="0.00008440" />
    </inertial>
    <visual>
      <origin
        xyz="0 0 0"
        rpy="0 0 0" />
      <geometry>
        <mesh
          filename="meshes/left_shoulder_pitch_link.STL" />
      </geometry>
      <material
        name="">
        <color
          rgba="0.752941176470588 0.752941176470588 0.752941176470588 1" />
      </material>
    </visual>
    <collision>
      <origin
        xyz="0 0 0"
        rpy="0 0 0" />
      <geometry>
        <mesh
          filename="meshes/left_shoulder_pitch_link.STL" />
      </geometry>
    </collision>
  </link>
  <joint
    name="left_shoulder_pitch_joint"
    type="revolute">
    <origin
      xyz="0 0.091 0.1368"
      rpy="0 0 0" />
    <parent
      link="waist_pitch_link" />
    <child
      link="left_shoulder_pitch_link" />
    <axis
      xyz="0 1 0" />
    <limit
      lower="-3.0892"
      upper="2.6704"
      effort="14"
      velocity="27.227" />
  </joint>
  <link
    name="left_shoulder_roll_link">
    <inertial>
      <origin
        xyz="-0.0180419825631693 0.00369351780457387 -0.0181767851872"
        rpy="0 0 0" />
      <mass
        value="0.03219968" />
      <inertia
        ixx="0.00001469"
        ixy="0.00000047"
        ixz="-0.00000232"
        iyy="0.00002843"
        iyz="0.00000155"
        izz="0.00002136" />
    </inertial>
    <visual>
      <origin
        xyz="0 0 0"
        rpy="0 0 0" />
      <geometry>
        <mesh
          filename="meshes/left_shoulder_roll_link.STL" />
      </geometry>
      <material
        name="">
        <color
          rgba="0.752941176470588 0.752941176470588 0.752941176470588 1" />
      </material>
    </visual>
    <collision>
      <origin
        xyz="0 0 0"
        rpy="0 0 0" />
      <geometry>
        <mesh
          filename="meshes/left_shoulder_roll_link.STL" />
      </geometry>
    </collision>
  </link>
  <joint
    name="left_shoulder_roll_joint"
    type="revolute">
    <origin
      xyz="0.022 0.03 0"
      rpy="0 0 0" />
    <parent
      link="left_shoulder_pitch_link" />
    <child
      link="left_shoulder_roll_link" />
    <axis
      xyz="1 0 0" />
    <limit
      lower="-1.5882"
      upper="2.2515"
      effort="5.5"
      velocity="10.472" />
  </joint>
  <link
    name="left_shoulder_yaw_link">
    <inertial>
      <origin
        xyz="0.00486938767406374 -0.00228807795991849 -0.0707352759041122"
        rpy="0 0 0" />
      <mass
        value="0.43025073" />
      <inertia
        ixx="0.00106792"
        ixy="0.00000505"
        ixz="0.00009812"
        iyy="0.00107487"
        iyz="-0.00004554"
        izz="0.00014443" />
    </inertial>
    <visual>
      <origin
        xyz="0 0 0"
        rpy="0 0 0" />
      <geometry>
        <mesh
          filename="meshes/left_shoulder_yaw_link.STL" />
      </geometry>
      <material
        name="">
        <color
          rgba="0.752941176470588 0.752941176470588 0.752941176470588 1" />
      </material>
    </visual>
    <collision>
      <origin
        xyz="0 0 0"
        rpy="0 0 0" />
      <geometry>
        <mesh
          filename="meshes/left_shoulder_yaw_link.STL" />
      </geometry>
    </collision>
  </link>
  <joint
    name="left_shoulder_yaw_joint"
    type="revolute">
    <origin
      xyz="-0.022 0.005 -0.04"
      rpy="0 0 0" />
    <parent
      link="left_shoulder_roll_link" />
    <child
      link="left_shoulder_yaw_link" />
    <axis
      xyz="0 0 1" />
    <limit
      lower="-2.618"
      upper="2.618"
      effort="5.5"
      velocity="10.472" />
  </joint>
  <link
    name="left_elbow_pitch_link">
    <inertial>
      <origin
        xyz="0.0671727834181094 -0.0119953975309839 -0.00959319624226312"
        rpy="0 0 0" />
      <mass
        value="0.04897494" />
      <inertia
        ixx="0.00001936"
        ixy="0.00001082"
        ixz="0.00000179"
        iyy="0.00011274"
        iyz="-0.00000099"
        izz="0.00011441" />
    </inertial>
    <visual>
      <origin
        xyz="0 0 0"
        rpy="0 0 0" />
      <geometry>
        <mesh
          filename="meshes/left_elbow_pitch_link.STL" />
      </geometry>
      <material
        name="">
        <color
          rgba="0.498039215686275 0.498039215686275 0.498039215686275 1" />
      </material>
    </visual>
    <collision>
      <origin
        xyz="0 0 0"
        rpy="0 0 0" />
      <geometry>
        <mesh
          filename="meshes/left_elbow_pitch_link.STL" />
      </geometry>
    </collision>
  </link>
  <joint
    name="left_elbow_pitch_joint"
    type="revolute">
    <origin
      xyz="0.01 0.016 -0.117"
      rpy="0 0 0" />
    <parent
      link="left_shoulder_yaw_link" />
    <child
      link="left_elbow_pitch_link" />
    <axis
      xyz="0 1 0" />
    <limit
      lower="-1.0472"
      upper="2.0944"
      effort="5.5"
      velocity="10.472" />
  </joint>
  <link
    name="right_shoulder_pitch_link">
    <inertial>
      <origin
        xyz="-0.000772680485948685 -0.0281035423352153 4.44089209850063E-16"
        rpy="0 0 0" />
      <mass
        value="0.22917007" />
      <inertia
        ixx="0.00007116"
        ixy="-0.00000034"
        ixz="-0.00000000"
        iyy="0.00007802"
        iyz="-0.00000000"
        izz="0.00008440" />
    </inertial>
    <visual>
      <origin
        xyz="0 0 0"
        rpy="0 0 0" />
      <geometry>
        <mesh
          filename="meshes/right_shoulder_pitch_link.STL" />
      </geometry>
      <material
        name="">
        <color
          rgba="0.752941176470588 0.752941176470588 0.752941176470588 1" />
      </material>
    </visual>
    <collision>
      <origin
        xyz="0 0 0"
        rpy="0 0 0" />
      <geometry>
        <mesh
          filename="meshes/right_shoulder_pitch_link.STL" />
      </geometry>
    </collision>
  </link>
  <joint
    name="right_shoulder_pitch_joint"
    type="revolute">
    <origin
      xyz="0 -0.091 0.1368"
      rpy="0 0 0" />
    <parent
      link="waist_pitch_link" />
    <child
      link="right_shoulder_pitch_link" />
    <axis
      xyz="0 1 0" />
    <limit
      lower="-3.0892"
      upper="2.6704"
      effort="14"
      velocity="27.2271" />
  </joint>
  <link
    name="right_shoulder_roll_link">
    <inertial>
      <origin
        xyz="-0.0180419825631695 -0.00369351780457422 -0.0181767851872001"
        rpy="0 0 0" />
      <mass
        value="0.03219968" />
      <inertia
        ixx="0.00001469"
        ixy="-0.00000047"
        ixz="-0.00000232"
        iyy="0.00002843"
        iyz="-0.00000155"
        izz="0.00002136" />
    </inertial>
    <visual>
      <origin
        xyz="0 0 0"
        rpy="0 0 0" />
      <geometry>
        <mesh
          filename="meshes/right_shoulder_roll_link.STL" />
      </geometry>
      <material
        name="">
        <color
          rgba="0.752941176470588 0.752941176470588 0.752941176470588 1" />
      </material>
    </visual>
    <collision>
      <origin
        xyz="0 0 0"
        rpy="0 0 0" />
      <geometry>
        <mesh
          filename="meshes/right_shoulder_roll_link.STL" />
      </geometry>
    </collision>
  </link>
  <joint
    name="right_shoulder_roll_joint"
    type="revolute">
    <origin
      xyz="0.022 -0.03 0"
      rpy="0 0 0" />
    <parent
      link="right_shoulder_pitch_link" />
    <child
      link="right_shoulder_roll_link" />
    <axis
      xyz="1 0 0" />
    <limit
      lower="-1.5882"
      upper="2.2515"
      effort="5.5"
      velocity="10.4719" />
  </joint>
  <link
    name="right_shoulder_yaw_link">
    <inertial>
      <origin
        xyz="0.00486949123812465 0.00228808503317014 -0.0707350502981907"
        rpy="0 0 0" />
      <mass
        value="0.43024648" />
      <inertia
        ixx="0.00106791"
        ixy="-0.00000505"
        ixz="0.00009812"
        iyy="0.00107486"
        iyz="0.00004554"
        izz="0.00014443" />
    </inertial>
    <visual>
      <origin
        xyz="0 0 0"
        rpy="0 0 0" />
      <geometry>
        <mesh
          filename="meshes/right_shoulder_yaw_link.STL" />
      </geometry>
      <material
        name="">
        <color
          rgba="0.752941176470588 0.752941176470588 0.752941176470588 1" />
      </material>
    </visual>
    <collision>
      <origin
        xyz="0 0 0"
        rpy="0 0 0" />
      <geometry>
        <mesh
          filename="meshes/right_shoulder_yaw_link.STL" />
      </geometry>
    </collision>
  </link>
  <joint
    name="right_shoulder_yaw_joint"
    type="revolute">
    <origin
      xyz="-0.022 -0.005 -0.04"
      rpy="0 0 0" />
    <parent
      link="right_shoulder_roll_link" />
    <child
      link="right_shoulder_yaw_link" />
    <axis
      xyz="0 0 1" />
    <limit
      lower="-2.618"
      upper="2.618"
      effort="5.5"
      velocity="10.472" />
  </joint>
  <link
    name="right_elbow_pitch_link">
    <inertial>
      <origin
        xyz="0.0671725852484883 0.011994271309719 -0.00959440018949753"
        rpy="0 0 0" />
      <mass
        value="0.04897497" />
      <inertia
        ixx="0.00001936"
        ixy="-0.00001082"
        ixz="0.00000179"
        iyy="0.00011274"
        iyz="0.00000099"
        izz="0.00011441" />
    </inertial>
    <visual>
      <origin
        xyz="0 0 0"
        rpy="0 0 0" />
      <geometry>
        <mesh
          filename="meshes/right_elbow_pitch_link.STL" />
      </geometry>
      <material
        name="">
        <color
          rgba="0.498039215686275 0.498039215686275 0.498039215686275 1" />
      </material>
    </visual>
    <collision>
      <origin
        xyz="0 0 0"
        rpy="0 0 0" />
      <geometry>
        <mesh
          filename="meshes/right_elbow_pitch_link.STL" />
      </geometry>
    </collision>
  </link>
  <joint
    name="right_elbow_pitch_joint"
    type="revolute">
    <origin
      xyz="0.01 -0.016 -0.117"
      rpy="0 0 0" />
    <parent
      link="right_shoulder_yaw_link" />
    <child
      link="right_elbow_pitch_link" />
    <axis
      xyz="0 1 0" />
    <limit
      lower="-1.0472"
      upper="2.0944"
      effort="5.5"
      velocity="10.4719" />
  </joint>
  <link
    name="head_Link">
    <inertial>
      <origin
        xyz="-0.000631428423385657 6.68186481878911E-08 0.0517704927072477"
        rpy="0 0 0" />
      <mass
        value="0.06555401" />
      <inertia
        ixx="0.00010552"
        ixy="-0.00000000"
        ixz="-0.00000007"
        iyy="0.00010397"
        iyz="-0.00000000"
        izz="0.00010623" />
    </inertial>
    <visual>
      <origin
        xyz="0 0 0"
        rpy="0 0 0" />
      <geometry>
        <mesh
          filename="meshes/head_Link.STL" />
      </geometry>
      <material
        name="">
        <color
          rgba="0.498039215686275 0.498039215686275 0.498039215686275 1" />
      </material>
    </visual>
    <collision>
      <origin
        xyz="0 0 0"
        rpy="0 0 0" />
      <geometry>
        <mesh
          filename="meshes/head_Link.STL" />
      </geometry>
    </collision>
  </link>
  <joint
    name="head_joint"
    type="fixed">
    <origin
      xyz="0 0 0.1788"
      rpy="0 0 0" />
    <parent
      link="waist_pitch_link" />
    <child
      link="head_Link" />
    <axis
      xyz="0 0 0" />
  </joint>
</robot>